[2025-04-11T16:52:24.935+0000] {taskinstance.py:1956} INFO - Dependencies all met for dep_context=non-requeueable deps ti=<TaskInstance: query_email_every_2hrs.send_email manual__2025-04-11T16:52:23.095963+00:00 [queued]>
[2025-04-11T16:52:24.942+0000] {taskinstance.py:1956} INFO - Dependencies all met for dep_context=requeueable deps ti=<TaskInstance: query_email_every_2hrs.send_email manual__2025-04-11T16:52:23.095963+00:00 [queued]>
[2025-04-11T16:52:24.943+0000] {taskinstance.py:2170} INFO - Starting attempt 1 of 2
[2025-04-11T16:52:24.955+0000] {taskinstance.py:2191} INFO - Executing <Task(EmailOperator): send_email> on 2025-04-11 16:52:23.095963+00:00
[2025-04-11T16:52:24.960+0000] {standard_task_runner.py:60} INFO - Started process 179 to run task
[2025-04-11T16:52:24.962+0000] {standard_task_runner.py:87} INFO - Running: ['***', 'tasks', 'run', 'query_email_every_2hrs', 'send_email', 'manual__2025-04-11T16:52:23.095963+00:00', '--job-id', '66', '--raw', '--subdir', 'DAGS_FOLDER/query_email_dag.py', '--cfg-path', '/tmp/tmpx62hogyu']
[2025-04-11T16:52:24.963+0000] {standard_task_runner.py:88} INFO - Job 66: Subtask send_email
[2025-04-11T16:52:24.978+0000] {logging_mixin.py:188} WARNING - /home/***/.local/lib/python3.8/site-packages/***/settings.py:194 DeprecationWarning: The sql_alchemy_conn option in [core] has been moved to the sql_alchemy_conn option in [database] - the old setting has been used, but please update your config.
[2025-04-11T16:52:25.007+0000] {task_command.py:423} INFO - Running <TaskInstance: query_email_every_2hrs.send_email manual__2025-04-11T16:52:23.095963+00:00 [running]> on host 88ab7e40fbb2
[2025-04-11T16:52:25.111+0000] {taskinstance.py:2480} INFO - Exporting env vars: AIRFLOW_CTX_DAG_OWNER='***' AIRFLOW_CTX_DAG_ID='query_email_every_2hrs' AIRFLOW_CTX_TASK_ID='send_email' AIRFLOW_CTX_EXECUTION_DATE='2025-04-11T16:52:23.095963+00:00' AIRFLOW_CTX_TRY_NUMBER='1' AIRFLOW_CTX_DAG_RUN_ID='manual__2025-04-11T16:52:23.095963+00:00'
[2025-04-11T16:52:25.123+0000] {base.py:83} INFO - Using connection ID 'smtp_default' for task execution.
[2025-04-11T16:52:25.124+0000] {email.py:270} INFO - Email alerting: attempt 1
[2025-04-11T16:52:25.126+0000] {taskinstance.py:2698} ERROR - Task failed with exception
Traceback (most recent call last):
  File "/home/airflow/.local/lib/python3.8/site-packages/airflow/models/taskinstance.py", line 433, in _execute_task
    result = execute_callable(context=context, **execute_callable_kwargs)
  File "/home/airflow/.local/lib/python3.8/site-packages/airflow/operators/email.py", line 79, in execute
    send_email(
  File "/home/airflow/.local/lib/python3.8/site-packages/airflow/utils/email.py", line 80, in send_email
    return backend(
  File "/home/airflow/.local/lib/python3.8/site-packages/airflow/utils/email.py", line 154, in send_email_smtp
    send_mime_email(e_from=mail_from, e_to=recipients, mime_msg=msg, conn_id=conn_id, dryrun=dryrun)
  File "/home/airflow/.local/lib/python3.8/site-packages/airflow/utils/email.py", line 272, in send_mime_email
    smtp_conn = _get_smtp_connection(smtp_host, smtp_port, smtp_timeout, smtp_ssl)
  File "/home/airflow/.local/lib/python3.8/site-packages/airflow/utils/email.py", line 316, in _get_smtp_connection
    return smtplib.SMTP(host=host, port=port, timeout=timeout)
  File "/usr/local/lib/python3.8/smtplib.py", line 255, in __init__
    (code, msg) = self.connect(host, port)
  File "/usr/local/lib/python3.8/smtplib.py", line 339, in connect
    self.sock = self._get_socket(host, port, self.timeout)
  File "/usr/local/lib/python3.8/smtplib.py", line 310, in _get_socket
    return socket.create_connection((host, port), timeout,
  File "/usr/local/lib/python3.8/socket.py", line 808, in create_connection
    raise err
  File "/usr/local/lib/python3.8/socket.py", line 796, in create_connection
    sock.connect(sa)
ConnectionRefusedError: [Errno 111] Connection refused
[2025-04-11T16:52:25.137+0000] {taskinstance.py:1138} INFO - Marking task as UP_FOR_RETRY. dag_id=query_email_every_2hrs, task_id=send_email, execution_date=20250411T165223, start_date=20250411T165224, end_date=20250411T165225
[2025-04-11T16:52:25.150+0000] {standard_task_runner.py:107} ERROR - Failed to execute job 66 for task send_email ([Errno 111] Connection refused; 179)
[2025-04-11T16:52:25.175+0000] {local_task_job_runner.py:234} INFO - Task exited with return code 1
[2025-04-11T16:52:25.193+0000] {taskinstance.py:3280} INFO - 0 downstream tasks scheduled from follow-on schedule check
