[2025-04-11T17:14:29.062+0000] {taskinstance.py:1956} INFO - Dependencies all met for dep_context=non-requeueable deps ti=<TaskInstance: query_email_every_2hrs.send_email manual__2025-04-11T17:12:24.607828+00:00 [queued]>
[2025-04-11T17:14:29.073+0000] {taskinstance.py:1956} INFO - Dependencies all met for dep_context=requeueable deps ti=<TaskInstance: query_email_every_2hrs.send_email manual__2025-04-11T17:12:24.607828+00:00 [queued]>
[2025-04-11T17:14:29.074+0000] {taskinstance.py:2170} INFO - Starting attempt 2 of 2
[2025-04-11T17:14:29.090+0000] {taskinstance.py:2191} INFO - Executing <Task(EmailOperator): send_email> on 2025-04-11 17:12:24.607828+00:00
[2025-04-11T17:14:29.099+0000] {standard_task_runner.py:60} INFO - Started process 205 to run task
[2025-04-11T17:14:29.103+0000] {standard_task_runner.py:87} INFO - Running: ['***', 'tasks', 'run', 'query_email_every_2hrs', 'send_email', 'manual__2025-04-11T17:12:24.607828+00:00', '--job-id', '84', '--raw', '--subdir', 'DAGS_FOLDER/query_email_dag.py', '--cfg-path', '/tmp/tmpi580fplk']
[2025-04-11T17:14:29.106+0000] {standard_task_runner.py:88} INFO - Job 84: Subtask send_email
[2025-04-11T17:14:29.124+0000] {logging_mixin.py:188} WARNING - /home/***/.local/lib/python3.8/site-packages/***/settings.py:194 DeprecationWarning: The sql_alchemy_conn option in [core] has been moved to the sql_alchemy_conn option in [database] - the old setting has been used, but please update your config.
[2025-04-11T17:14:29.169+0000] {task_command.py:423} INFO - Running <TaskInstance: query_email_every_2hrs.send_email manual__2025-04-11T17:12:24.607828+00:00 [running]> on host 88ab7e40fbb2
[2025-04-11T17:14:29.267+0000] {taskinstance.py:2480} INFO - Exporting env vars: AIRFLOW_CTX_DAG_OWNER='***' AIRFLOW_CTX_DAG_ID='query_email_every_2hrs' AIRFLOW_CTX_TASK_ID='send_email' AIRFLOW_CTX_EXECUTION_DATE='2025-04-11T17:12:24.607828+00:00' AIRFLOW_CTX_TRY_NUMBER='2' AIRFLOW_CTX_DAG_RUN_ID='manual__2025-04-11T17:12:24.607828+00:00'
[2025-04-11T17:14:29.282+0000] {logging_mixin.py:188} WARNING - /home/***/.local/lib/python3.8/site-packages/***/utils/email.py:154 RemovedInAirflow3Warning: Fetching SMTP credentials from configuration variables will be deprecated in a future release. Please set credentials using a connection instead.
[2025-04-11T17:14:29.284+0000] {configuration.py:1046} WARNING - section/key [smtp/smtp_user] not found in config
[2025-04-11T17:14:29.284+0000] {email.py:270} INFO - Email alerting: attempt 1
[2025-04-11T17:14:29.286+0000] {taskinstance.py:2698} ERROR - Task failed with exception
Traceback (most recent call last):
  File "/home/airflow/.local/lib/python3.8/site-packages/airflow/models/taskinstance.py", line 433, in _execute_task
    result = execute_callable(context=context, **execute_callable_kwargs)
  File "/home/airflow/.local/lib/python3.8/site-packages/airflow/operators/email.py", line 79, in execute
    send_email(
  File "/home/airflow/.local/lib/python3.8/site-packages/airflow/utils/email.py", line 80, in send_email
    return backend(
  File "/home/airflow/.local/lib/python3.8/site-packages/airflow/utils/email.py", line 154, in send_email_smtp
    send_mime_email(e_from=mail_from, e_to=recipients, mime_msg=msg, conn_id=conn_id, dryrun=dryrun)
  File "/home/airflow/.local/lib/python3.8/site-packages/airflow/utils/email.py", line 272, in send_mime_email
    smtp_conn = _get_smtp_connection(smtp_host, smtp_port, smtp_timeout, smtp_ssl)
  File "/home/airflow/.local/lib/python3.8/site-packages/airflow/utils/email.py", line 316, in _get_smtp_connection
    return smtplib.SMTP(host=host, port=port, timeout=timeout)
  File "/usr/local/lib/python3.8/smtplib.py", line 255, in __init__
    (code, msg) = self.connect(host, port)
  File "/usr/local/lib/python3.8/smtplib.py", line 339, in connect
    self.sock = self._get_socket(host, port, self.timeout)
  File "/usr/local/lib/python3.8/smtplib.py", line 310, in _get_socket
    return socket.create_connection((host, port), timeout,
  File "/usr/local/lib/python3.8/socket.py", line 808, in create_connection
    raise err
  File "/usr/local/lib/python3.8/socket.py", line 796, in create_connection
    sock.connect(sa)
ConnectionRefusedError: [Errno 111] Connection refused
[2025-04-11T17:14:29.299+0000] {taskinstance.py:1138} INFO - Marking task as FAILED. dag_id=query_email_every_2hrs, task_id=send_email, execution_date=20250411T171224, start_date=20250411T171429, end_date=20250411T171429
[2025-04-11T17:14:29.313+0000] {standard_task_runner.py:107} ERROR - Failed to execute job 84 for task send_email ([Errno 111] Connection refused; 205)
[2025-04-11T17:14:29.356+0000] {local_task_job_runner.py:234} INFO - Task exited with return code 1
[2025-04-11T17:14:29.374+0000] {taskinstance.py:3280} INFO - 0 downstream tasks scheduled from follow-on schedule check
